Workbook
Name Slicer_Category: #N/A
Name Slicer_Category_Type: #N/A
Name Slicer_Month: #N/A

Sheet Main Sheet
A1: Account | B1: Date | C1: Description | D1: Sub-category | E1: Category | F1: Category Type | G1: Debit | H1: Credit | I1: Amount | J1: Year | K1: Month | M1: Expense | N1: 1
A2: Checking | B2: 44200 | C2: ACME Pty Ltd | D2: Salary | E2: Salary | F2: Income | H2: 4000 | I2: =IF(tbl_main[[#This Row],[Debit]]<>"",-tbl_main[[#This Row],[Debit]],tbl_main[[#This Row],[Credit]]) -> 4000 | J2: =YEAR(tbl_main[[#This Row],[Date]]) -> 2021 | K2: =TEXT(tbl_main[[#This Row],[Date]],"mmm") -> Jan | M2: {=_xlfn.UNIQUE(_xlfn._xlws.FILTER(tbl_main[Category],tbl_main[Category Type]=M1))} -> Dining Out | N2: {=_xlfn.ARRAYTOTEXT(_xlfn.UNIQUE(_xlfn._xlws.FILTER(tbl_main[Sub-category],tbl_main[Category]=M2)))} -> Coffee, Restaurant
A3: Credit | B3: 44200 | C3: Ground | D3: Coffee | E3: Dining Out | F3: Expense | G3: 5 | I3: =IF(tbl_main[[#This Row],[Debit]]<>"",-tbl_main[[#This Row],[Debit]],tbl_main[[#This Row],[Credit]]) -> -5 | J3: =YEAR(tbl_main[[#This Row],[Date]]) -> 2021 | K3: =TEXT(tbl_main[[#This Row],[Date]],"mmm") -> Jan | M3: Living Expenses | N3: {=_xlfn.ARRAYTOTEXT(_xlfn.UNIQUE(_xlfn._xlws.FILTER(tbl_main[Sub-category],tbl_main[Category]=M3)))} -> Rent, Groceries, Gas/Electrics, Phone
A4: Checking | B4: 44201 | C4: Estate Mgt. | D4: Rent | E4: Living Expenses | F4: Expense | G4: 900 | I4: =IF(tbl_main[[#This Row],[Debit]]<>"",-tbl_main[[#This Row],[Debit]],tbl_main[[#This Row],[Credit]]) -> -900 | J4: =YEAR(tbl_main[[#This Row],[Date]]) -> 2021 | K4: =TEXT(tbl_main[[#This Row],[Date]],"mmm") -> Jan | M4: Transport | N4: {=_xlfn.ARRAYTOTEXT(_xlfn.UNIQUE(_xlfn._xlws.FILTER(tbl_main[Sub-category],tbl_main[Category]=M4)))} -> Entertainment, MV Fuel, Taxi
A5: Checking | B5: 44201 | C5: Finance Co. | D5: Entertainment | E5: Transport | F5: Expense | G5: 150 | I5: =IF(tbl_main[[#This Row],[Debit]]<>"",-tbl_main[[#This Row],[Debit]],tbl_main[[#This Row],[Credit]]) -> -150 | J5: =YEAR(tbl_main[[#This Row],[Date]]) -> 2021 | K5: =TEXT(tbl_main[[#This Row],[Date]],"mmm") -> Jan | M5: Discretionary | N5: {=_xlfn.ARRAYTOTEXT(_xlfn.UNIQUE(_xlfn._xlws.FILTER(tbl_main[Sub-category],tbl_main[Category]=M5)))} -> Entertainment, Clothes, Gym, Gifts, Furnishings
A6: Credit | B6: 44201 | C6: Ground | D6: Coffee | E6: Dining Out | F6: Expense | G6: 5 | I6: =IF(tbl_main[[#This Row],[Debit]]<>"",-tbl_main[[#This Row],[Debit]],tbl_main[[#This Row],[Credit]]) -> -5 | J6: =YEAR(tbl_main[[#This Row],[Date]]) -> 2021 | K6: =TEXT(tbl_main[[#This Row],[Date]],"mmm") -> Jan | M6: Medical | N6: {=_xlfn.ARRAYTOTEXT(_xlfn.UNIQUE(_xlfn._xlws.FILTER(tbl_main[Sub-category],tbl_main[Category]=M6)))} -> Doctor
A7: Credit | B7: 44202 | C7: Ground | D7: Coffee | E7: Dining Out | F7: Expense | G7: 5 | I7: =IF(tbl_main[[#This Row],[Debit]]<>"",-tbl_main[[#This Row],[Debit]],tbl_main[[#This Row],[Credit]]) -> -5 | J7: =YEAR(tbl_main[[#This Row],[Date]]) -> 2021 | K7: =TEXT(tbl_main[[#This Row],[Date]],"mmm") -> Jan | M7: Charity | N7: {=_xlfn.ARRAYTOTEXT(_xlfn.UNIQUE(_xlfn._xlws.FILTER(tbl_main[Sub-category],tbl_main[Category]=M7)))} -> Donation
A8: Credit | B8: 44203 | C8: Ground | D8: Coffee | E8: Dining Out | F8: Expense | G8: 5 | I8: =IF(tbl_main[[#This Row],[Debit]]<>"",-tbl_main[[#This Row],[Debit]],tbl_main[[#This Row],[Credit]]) -> -5 | J8: =YEAR(tbl_main[[#This Row],[Date]]) -> 2021 | K8: =TEXT(tbl_main[[#This Row],[Date]],"mmm") -> Jan
A9: Credit | B9: 44204 | C9: Ground | D9: Coffee | E9: Dining Out | F9: Expense | G9: 5 | I9: =IF(tbl_main[[#This Row],[Debit]]<>"",-tbl_main[[#This Row],[Debit]],tbl_main[[#This Row],[Credit]]) -> -5 | J9: =YEAR(tbl_main[[#This Row],[Date]]) -> 2021 | K9: =TEXT(tbl_main[[#This Row],[Date]],"mmm") -> Jan
A10: Credit | B10: 44204 | C10: Green's | D10: Groceries | E10: Living Expenses | F10: Expense | G10: 155 | I10: =IF(tbl_main[[#This Row],[Debit]]<>"",-tbl_main[[#This Row],[Debit]],tbl_main[[#This Row],[Credit]]) -> -155 | J10: =YEAR(tbl_main[[#This Row],[Date]]) -> 2021 | K10: =TEXT(tbl_main[[#This Row],[Date]],"mmm") -> Jan
A11: Checking | B11: 44207 | C11: Elec. Co. | D11: Gas/Electrics | E11: Living Expenses | F11: Expense | G11: 50 | I11: =IF(tbl_main[[#This Row],[Debit]]<>"",-tbl_main[[#This Row],[Debit]],tbl_main[[#This Row],[Credit]]) -> -50 | J11: =YEAR(tbl_main[[#This Row],[Date]]) -> 2021 | K11: =TEXT(tbl_main[[#This Row],[Date]],"mmm") -> Jan
A12: Credit | B12: 44207 | C12: Ground | D12: Coffee | E12: Dining Out | F12: Expense | G12: 5 | I12: =IF(tbl_main[[#This Row],[Debit]]<>"",-tbl_main[[#This Row],[Debit]],tbl_main[[#This Row],[Credit]]) -> -5 | J12: =YEAR(tbl_main[[#This Row],[Date]]) -> 2021 | K12: =TEXT(tbl_main[[#This Row],[Date]],"mmm") -> Jan
A13: Credit | B13: 44208 | C13: Ground | D13: Coffee | E13: Dining Out | F13: Expense | G13: 5 | I13: =IF(tbl_main[[#This Row],[Debit]]<>"",-tbl_main[[#This Row],[Debit]],tbl_main[[#This Row],[Credit]]) -> -5 | J13: =YEAR(tbl_main[[#This Row],[Date]]) -> 2021 | K13: =TEXT(tbl_main[[#This Row],[Date]],"mmm") -> Jan
A14: Credit | B14: 44209 | C14: Fuel. Co | D14: MV Fuel | E14: Transport | F14: Expense | G14: 77 | I14: =IF(tbl_main[[#This Row],[Debit]]<>"",-tbl_main[[#This Row],[Debit]],tbl_main[[#This Row],[Credit]]) -> -77 | J14: =YEAR(tbl_main[[#This Row],[Date]]) -> 2021 | K14: =TEXT(tbl_main[[#This Row],[Date]],"mmm") -> Jan
A15: Credit | B15: 44209 | C15: Ground | D15: Coffee | E15: Dining Out | F15: Expense | G15: 5 | I15: =IF(tbl_main[[#This Row],[Debit]]<>"",-tbl_main[[#This Row],[Debit]],tbl_main[[#This Row],[Credit]]) -> -5 | J15: =YEAR(tbl_main[[#This Row],[Date]]) -> 2021 | K15: =TEXT(tbl_main[[#This Row],[Date]],"mmm") -> Jan
A16: Credit | B16: 44210 | C16: Ground | D16: Coffee | E16: Dining Out | F16: Expense | G16: 5 | I16: =IF(tbl_main[[#This Row],[Debit]]<>"",-tbl_main[[#This Row],[Debit]],tbl_main[[#This Row],[Credit]]) -> -5 | J16: =YEAR(tbl_main[[#This Row],[Date]]) -> 2021 | K16: =TEXT(tbl_main[[#This Row],[Date]],"mmm") -> Jan
A17: Credit | B17: 44211 | C17: Green's | D17: Groceries | E17: Living Expenses | F17: Expense | G17: 135 | I17: =IF(tbl_main[[#This Row],[Debit]]<>"",-tbl_main[[#This Row],[Debit]],tbl_main[[#This Row],[Credit]]) -> -135 | J17: =YEAR(tbl_main[[#This Row],[Date]]) -> 2021 | K17: =TEXT(tbl_main[[#This Row],[Date]],"mmm") -> Jan
A18: Credit | B18: 44211 | C18: Ground | D18: Coffee | E18: Dining Out | F18: Expense | G18: 5 | I18: =IF(tbl_main[[#This Row],[Debit]]<>"",-tbl_main[[#This Row],[Debit]],tbl_main[[#This Row],[Credit]]) -> -5 | J18: =YEAR(tbl_main[[#This Row],[Date]]) -> 2021 | K18: =TEXT(tbl_main[[#This Row],[Date]],"mmm") -> Jan
A19: Credit | B19: 44212 | C19: Ground | D19: Coffee | E19: Dining Out | F19: Expense | G19: 5 | I19: =IF(tbl_main[[#This Row],[Debit]]<>"",-tbl_main[[#This Row],[Debit]],tbl_main[[#This Row],[Credit]]) -> -5 | J19: =YEAR(tbl_main[[#This Row],[Date]]) -> 2021 | K19: =TEXT(tbl_main[[#This Row],[Date]],"mmm") -> Jan
... A48: Credit | B48: 44227 | C48: Taxi Co. | D48: Taxi | E48: Transport | F48: Expense | G48: 23 | I48: =IF(tbl_main[[#This Row],[Debit]]<>"",-tbl_main[[#This Row],[Debit]],tbl_main[[#This Row],[Credit]]) -> -23 | J48: =YEAR(tbl_main[[#This Row],[Date]]) -> 2021 | K48: =TEXT(tbl_main[[#This Row],[Date]],"mmm") -> Jan
A49: Checking | B49: 44228 | C49: ACME Pty Ltd | D49: Salary | E49: Salary | F49: Income | H49: 4000 | I49: =IF(tbl_main[[#This Row],[Debit]]<>"",-tbl_main[[#This Row],[Debit]],tbl_main[[#This Row],[Credit]]) -> 4000 | J49: =YEAR(tbl_main[[#This Row],[Date]]) -> 2021 | K49: =TEXT(tbl_main[[#This Row],[Date]],"mmm") -> Feb
A50: Credit | B50: 44228 | C50: Ground | D50: Coffee | E50: Dining Out | F50: Expense | G50: 5 | I50: =IF(tbl_main[[#This Row],[Debit]]<>"",-tbl_main[[#This Row],[Debit]],tbl_main[[#This Row],[Credit]]) -> -5 | J50: =YEAR(tbl_main[[#This Row],[Date]]) -> 2021 | K50: =TEXT(tbl_main[[#This Row],[Date]],"mmm") -> Feb
A51: Checking | B51: 44229 | C51: Estate Mgt. | D51: Rent | E51: Living Expenses | F51: Expense | G51: 900 | I51: =IF(tbl_main[[#This Row],[Debit]]<>"",-tbl_main[[#This Row],[Debit]],tbl_main[[#This Row],[Credit]]) -> -900 | J51: =YEAR(tbl_main[[#This Row],[Date]]) -> 2021 | K51: =TEXT(tbl_main[[#This Row],[Date]],"mmm") -> Feb
A52: Checking | B52: 44229 | C52: Finance Co. | D52: Entertainment | E52: Transport | F52: Expense | G52: 150 | I52: =IF(tbl_main[[#This Row],[Debit]]<>"",-tbl_main[[#This Row],[Debit]],tbl_main[[#This Row],[Credit]]) -> -150 | J52: =YEAR(tbl_main[[#This Row],[Date]]) -> 2021 | K52: =TEXT(tbl_main[[#This Row],[Date]],"mmm") -> Feb
A53: Credit | B53: 44229 | C53: Ground | D53: Coffee | E53: Dining Out | F53: Expense | G53: 5 | I53: =IF(tbl_main[[#This Row],[Debit]]<>"",-tbl_main[[#This Row],[Debit]],tbl_main[[#This Row],[Credit]]) -> -5 | J53: =YEAR(tbl_main[[#This Row],[Date]]) -> 2021 | K53: =TEXT(tbl_main[[#This Row],[Date]],"mmm") -> Feb
A54: Credit | B54: 44230 | C54: Ground | D54: Coffee | E54: Dining Out | F54: Expense | G54: 5 | I54: =IF(tbl_main[[#This Row],[Debit]]<>"",-tbl_main[[#This Row],[Debit]],tbl_main[[#This Row],[Credit]]) -> -5 | J54: =YEAR(tbl_main[[#This Row],[Date]]) -> 2021 | K54: =TEXT(tbl_main[[#This Row],[Date]],"mmm") -> Feb
A55: Credit | B55: 44231 | C55: Ground | D55: Coffee | E55: Dining Out | F55: Expense | G55: 5 | I55: =IF(tbl_main[[#This Row],[Debit]]<>"",-tbl_main[[#This Row],[Debit]],tbl_main[[#This Row],[Credit]]) -> -5 | J55: =YEAR(tbl_main[[#This Row],[Date]]) -> 2021 | K55: =TEXT(tbl_main[[#This Row],[Date]],"mmm") -> Feb
A56: Credit | B56: 44232 | C56: Ground | D56: Coffee | E56: Dining Out | F56: Expense | G56: 5 | I56: =IF(tbl_main[[#This Row],[Debit]]<>"",-tbl_main[[#This Row],[Debit]],tbl_main[[#This Row],[Credit]]) -> -5 | J56: =YEAR(tbl_main[[#This Row],[Date]]) -> 2021 | K56: =TEXT(tbl_main[[#This Row],[Date]],"mmm") -> Feb
A57: Credit | B57: 44232 | C57: Green's | D57: Groceries | E57: Living Expenses | F57: Expense | G57: 205 | I57: =IF(tbl_main[[#This Row],[Debit]]<>"",-tbl_main[[#This Row],[Debit]],tbl_main[[#This Row],[Credit]]) -> -205 | J57: =YEAR(tbl_main[[#This Row],[Date]]) -> 2021 | K57: =TEXT(tbl_main[[#This Row],[Date]],"mmm") -> Feb
A58: Checking | B58: 44235 | C58: Elec. Co. | D58: Gas/Electrics | E58: Living Expenses | F58: Expense | G58: 51.1 | I58: =IF(tbl_main[[#This Row],[Debit]]<>"",-tbl_main[[#This Row],[Debit]],tbl_main[[#This Row],[Credit]]) -> -51.1 | J58: =YEAR(tbl_main[[#This Row],[Date]]) -> 2021 | K58: =TEXT(tbl_main[[#This Row],[Date]],"mmm") -> Feb
A59: Credit | B59: 44235 | C59: Ground | D59: Coffee | E59: Dining Out | F59: Expense | G59: 5 | I59: =IF(tbl_main[[#This Row],[Debit]]<>"",-tbl_main[[#This Row],[Debit]],tbl_main[[#This Row],[Credit]]) -> -5 | J59: =YEAR(tbl_main[[#This Row],[Date]]) -> 2021 | K59: =TEXT(tbl_main[[#This Row],[Date]],"mmm") -> Feb
A60: Credit | B60: 44236 | C60: Ground | D60: Coffee | E60: Dining Out | F60: Expense | G60: 5 | I60: =IF(tbl_main[[#This Row],[Debit]]<>"",-tbl_main[[#This Row],[Debit]],tbl_main[[#This Row],[Credit]]) -> -5 | J60: =YEAR(tbl_main[[#This Row],[Date]]) -> 2021 | K60: =TEXT(tbl_main[[#This Row],[Date]],"mmm") -> Feb
A61: Credit | B61: 44237 | C61: Fuel. Co | D61: MV Fuel | E61: Transport | F61: Expense | G61: 78 | I61: =IF(tbl_main[[#This Row],[Debit]]<>"",-tbl_main[[#This Row],[Debit]],tbl_main[[#This Row],[Credit]]) -> -78 | J61: =YEAR(tbl_main[[#This Row],[Date]]) -> 2021 | K61: =TEXT(tbl_main[[#This Row],[Date]],"mmm") -> Feb
... A94: Credit | B94: 44255 | C94: Taxi Co. | D94: Taxi | E94: Transport | F94: Expense | G94: 24.1 | I94: =IF(tbl_main[[#This Row],[Debit]]<>"",-tbl_main[[#This Row],[Debit]],tbl_main[[#This Row],[Credit]]) -> -24.1 | J94: =YEAR(tbl_main[[#This Row],[Date]]) -> 2021 | K94: =TEXT(tbl_main[[#This Row],[Date]],"mmm") -> Feb
A95: Checking | B95: 44256 | C95: ACME Pty Ltd | D95: Salary | E95: Salary | F95: Income | H95: 4000 | I95: =IF(tbl_main[[#This Row],[Debit]]<>"",-tbl_main[[#This Row],[Debit]],tbl_main[[#This Row],[Credit]]) -> 4000 | J95: =YEAR(tbl_main[[#This Row],[Date]]) -> 2021 | K95: =TEXT(tbl_main[[#This Row],[Date]],"mmm") -> Mar
A96: Credit | B96: 44256 | C96: Ground | D96: Coffee | E96: Dining Out | F96: Expense | G96: 5 | I96: =IF(tbl_main[[#This Row],[Debit]]<>"",-tbl_main[[#This Row],[Debit]],tbl_main[[#This Row],[Credit]]) -> -5 | J96: =YEAR(tbl_main[[#This Row],[Date]]) -> 2021 | K96: =TEXT(tbl_main[[#This Row],[Date]],"mmm") -> Mar
A97: Checking | B97: 44257 | C97: Estate Mgt. | D97: Rent | E97: Living Expenses | F97: Expense | G97: 900 | I97: =IF(tbl_main[[#This Row],[Debit]]<>"",-tbl_main[[#This Row],[Debit]],tbl_main[[#This Row],[Credit]]) -> -900 | J97: =YEAR(tbl_main[[#This Row],[Date]]) -> 2021 | K97: =TEXT(tbl_main[[#This Row],[Date]],"mmm") -> Mar
A98: Checking | B98: 44257 | C98: Finance Co. | D98: Entertainment | E98: Transport | F98: Expense | G98: 150 | I98: =IF(tbl_main[[#This Row],[Debit]]<>"",-tbl_main[[#This Row],[Debit]],tbl_main[[#This Row],[Credit]]) -> -150 | J98: =YEAR(tbl_main[[#This Row],[Date]]) -> 2021 | K98: =TEXT(tbl_main[[#This Row],[Date]],"mmm") -> Mar
A99: Credit | B99: 44257 | C99: Ground | D99: Coffee | E99: Dining Out | F99: Expense | G99: 5 | I99: =IF(tbl_main[[#This Row],[Debit]]<>"",-tbl_main[[#This Row],[Debit]],tbl_main[[#This Row],[Credit]]) -> -5 | J99: =YEAR(tbl_main[[#This Row],[Date]]) -> 2021 | K99: =TEXT(tbl_main[[#This Row],[Date]],"mmm") -> Mar
A100: Credit | B100: 44258 | C100: Ground | D100: Coffee | E100: Dining Out | F100: Expense | G100: 5 | I100: =IF(tbl_main[[#This Row],[Debit]]<>"",-tbl_main[[#This Row],[Debit]],tbl_main[[#This Row],[Credit]]) -> -5 | J100: =YEAR(tbl_main[[#This Row],[Date]]) -> 2021 | K100: =TEXT(tbl_main[[#This Row],[Date]],"mmm") -> Mar
...

Sheet Income & Expenses 2021
B2: Income & Expenses 2021
B4: Figures in USD | D4: {=_xlfn.LET(_xlpm.x,DATE(2025,_xlfn.SEQUENCE(12),1), TRANSPOSE(TEXT(_xlpm.x,"MMMM")))} -> January | E4: February | F4: March | G4: April | H4: May | I4: June | J4: July | K4: August | L4: September | M4: October | N4: November | O4: December | Q4: Total
B5: Income:
B6: Basic Salary | D6: {=_xlfn._xlws.FILTER('Main Sheet'!$H$2:$H$564,(MONTH('Main Sheet'!$B$2:$B$564)=(COLUMN(D6)-3))*('Main Sheet'!$H$2:$H$564<>""))} -> 4000 | E6: {=_xlfn._xlws.FILTER('Main Sheet'!$H$2:$H$564,(MONTH('Main Sheet'!$B$2:$B$564)=(COLUMN(E6)-3))*('Main Sheet'!$H$2:$H$564<>""))} -> 4000 | F6: {=_xlfn._xlws.FILTER('Main Sheet'!$H$2:$H$564,(MONTH('Main Sheet'!$B$2:$B$564)=(COLUMN(F6)-3))*('Main Sheet'!$H$2:$H$564<>""))} -> 4000 | G6: {=_xlfn._xlws.FILTER('Main Sheet'!$H$2:$H$564,(MONTH('Main Sheet'!$B$2:$B$564)=(COLUMN(G6)-3))*('Main Sheet'!$H$2:$H$564<>""))} -> 4000 | H6: {=_xlfn._xlws.FILTER('Main Sheet'!$H$2:$H$564,(MONTH('Main Sheet'!$B$2:$B$564)=(COLUMN(H6)-3))*('Main Sheet'!$H$2:$H$564<>""))} -> 4000 | I6: {=_xlfn._xlws.FILTER('Main Sheet'!$H$2:$H$564,(MONTH('Main Sheet'!$B$2:$B$564)=(COLUMN(I6)-3))*('Main Sheet'!$H$2:$H$564<>""))} -> 4000 | J6: {=_xlfn._xlws.FILTER('Main Sheet'!$H$2:$H$564,(MONTH('Main Sheet'!$B$2:$B$564)=(COLUMN(J6)-3))*('Main Sheet'!$H$2:$H$564<>""))} -> 4000 | K6: {=_xlfn._xlws.FILTER('Main Sheet'!$H$2:$H$564,(MONTH('Main Sheet'!$B$2:$B$564)=(COLUMN(K6)-3))*('Main Sheet'!$H$2:$H$564<>""))} -> 4000 | ... O6: {=_xlfn._xlws.FILTER('Main Sheet'!$H$2:$H$564,(MONTH('Main Sheet'!$B$2:$B$564)=(COLUMN(O6)-3))*('Main Sheet'!$H$2:$H$564<>""))} -> 4000 | Q6: =IF(ISNUMBER(D6)=TRUE,SUM($D6:$O6),"") -> 48000
B7: Bonus | D7: 0 | E7: 0 | F7: 0 | G7: 0 | H7: 0 | I7: 0 | J7: 0 | K7: 0 | L7: 0 | M7: 0 | N7: 0 | O7: 0 | Q7: =IF(ISNUMBER(D7)=TRUE,SUM($D7:$O7),"") -> 0
B8: Side Hustle | D8: 0 | E8: 0 | F8: 0 | G8: 0 | H8: 0 | I8: 0 | J8: 0 | K8: 0 | L8: 0 | M8: 0 | N8: 0 | O8: 0 | Q8: =IF(ISNUMBER(D8)=TRUE,SUM($D8:$O8),"") -> 0
B9: Total Income | D9: =SUM(D6:D8) -> 4000 | E9: =SUM(E6:E8) -> 4000 | F9: =SUM(F6:F8) -> 4000 | G9: =SUM(G6:G8) -> 4000 | H9: =SUM(H6:H8) -> 4000 | I9: =SUM(I6:I8) -> 4000 | J9: =SUM(J6:J8) -> 4000 | K9: =SUM(K6:K8) -> 4000 | ... O9: =SUM(O6:O8) -> 4000 | Q9: =IF(ISNUMBER(D9)=TRUE,SUM($D9:$O9),"") -> 48000
Q10: =IF(ISNUMBER(D10)=TRUE,SUM($D10:$O10),"")
B11: Figures in USD | D11: {=_xlfn.LET(_xlpm.x,DATE(2025,_xlfn.SEQUENCE(12),1), TRANSPOSE(TEXT(_xlpm.x,"MMMM")))} -> January | E11: February | F11: March | G11: April | H11: May | I11: June | J11: July | K11: August | L11: September | M11: October | N11: November | O11: December | Q11: =IF(ISNUMBER(D11)=TRUE,SUM($D11:$O11),"")
B12: Expenses: | Q12: =IF(ISNUMBER(D12)=TRUE,SUM($D12:$O12),"")
B13: {=_xlfn._xlws.SORT(_xlfn.UNIQUE(_xlfn._xlws.FILTER(tbl_main[Category],tbl_main[Category Type]<>"Income")))} -> Charity | C13: {=_xlfn.LET(_xlpm.x,_xlfn.UNIQUE(_xlfn._xlws.FILTER(tbl_main[Sub-category],tbl_main[Category]='Income & Expenses 2021'!B13)), _xlfn.ARRAYTOTEXT(_xlfn._xlws.SORT(_xlpm.x)))} -> Donation | D13: {=_xlfn.LET(_xlpm.x,_xlfn._xlws.FILTER('Main Sheet'!$G$2:$G$564,(MONTH('Main Sheet'!$B$2:$B$564) = (COLUMN('Income & Expenses 2021'!D6) -3)) * ('Main Sheet'!$E$2:$E$564='Income & Expenses 2021'!$B13),0), SUM(_xlpm.x))} -> 70 | E13: {=_xlfn.LET(_xlpm.x,_xlfn._xlws.FILTER('Main Sheet'!$G$2:$G$564,(MONTH('Main Sheet'!$B$2:$B$564) = (COLUMN('Income & Expenses 2021'!E6) -3)) * ('Main Sheet'!$E$2:$E$564='Income & Expenses 2021'!$B13),0), SUM(_xlpm.x))} -> 55 | F13: {=_xlfn.LET(_xlpm.x,_xlfn._xlws.FILTER('Main Sheet'!$G$2:$G$564,(MONTH('Main Sheet'!$B$2:$B$564) = (COLUMN('Income & Expenses 2021'!F6) -3)) * ('Main Sheet'!$E$2:$E$564='Income & Expenses 2021'!$B13),0), SUM(_xlpm.x))} -> 55 | G13: {=_xlfn.LET(_xlpm.x,_xlfn._xlws.FILTER('Main Sheet'!$G$2:$G$564,(MONTH('Main Sheet'!$B$2:$B$564) = (COLUMN('Income & Expenses 2021'!G6) -3)) * ('Main Sheet'!$E$2:$E$564='Income & Expenses 2021'!$B13),0), SUM(_xlpm.x))} -> 55 | H13: {=_xlfn.LET(_xlpm.x,_xlfn._xlws.FILTER('Main Sheet'!$G$2:$G$564,(MONTH('Main Sheet'!$B$2:$B$564) = (COLUMN('Income & Expenses 2021'!H6) -3)) * ('Main Sheet'!$E$2:$E$564='Income & Expenses 2021'!$B13),0), SUM(_xlpm.x))} -> 55 | I13: {=_xlfn.LET(_xlpm.x,_xlfn._xlws.FILTER('Main Sheet'!$G$2:$G$564,(MONTH('Main Sheet'!$B$2:$B$564) = (COLUMN('Income & Expenses 2021'!I6) -3)) * ('Main Sheet'!$E$2:$E$564='Income & Expenses 2021'!$B13),0), SUM(_xlpm.x))} -> 55 | J13: {=_xlfn.LET(_xlpm.x,_xlfn._xlws.FILTER('Main Sheet'!$G$2:$G$564,(MONTH('Main Sheet'!$B$2:$B$564) = (COLUMN('Income & Expenses 2021'!J6) -3)) * ('Main Sheet'!$E$2:$E$564='Income & Expenses 2021'!$B13),0), SUM(_xlpm.x))} -> 55 | K13: {=_xlfn.LET(_xlpm.x,_xlfn._xlws.FILTER('Main Sheet'!$G$2:$G$564,(MONTH('Main Sheet'!$B$2:$B$564) = (COLUMN('Income & Expenses 2021'!K6) -3)) * ('Main Sheet'!$E$2:$E$564='Income & Expenses 2021'!$B13),0), SUM(_xlpm.x))} -> 55 | ... O13: {=_xlfn.LET(_xlpm.x,_xlfn._xlws.FILTER('Main Sheet'!$G$2:$G$564,(MONTH('Main Sheet'!$B$2:$B$564) = (COLUMN('Income & Expenses 2021'!O6) -3)) * ('Main Sheet'!$E$2:$E$564='Income & Expenses 2021'!$B13),0), SUM(_xlpm.x))} -> 0 | Q13: =IF(ISNUMBER(D13)=TRUE,SUM($D13:$O13),"") -> 620
B14: Dining Out | C14: {=_xlfn.LET(_xlpm.x,_xlfn.UNIQUE(_xlfn._xlws.FILTER(tbl_main[Sub-category],tbl_main[Category]='Income & Expenses 2021'!B14)), _xlfn.ARRAYTOTEXT(_xlfn._xlws.SORT(_xlpm.x)))} -> Coffee, Restaurant | D14: {=_xlfn.LET(_xlpm.x,_xlfn._xlws.FILTER('Main Sheet'!$G$2:$G$564,(MONTH('Main Sheet'!$B$2:$B$564) = (COLUMN('Income & Expenses 2021'!D7) -3)) * ('Main Sheet'!$E$2:$E$564='Income & Expenses 2021'!$B14),0), SUM(_xlpm.x))} -> 206 | E14: {=_xlfn.LET(_xlpm.x,_xlfn._xlws.FILTER('Main Sheet'!$G$2:$G$564,(MONTH('Main Sheet'!$B$2:$B$564) = (COLUMN('Income & Expenses 2021'!E7) -3)) * ('Main Sheet'!$E$2:$E$564='Income & Expenses 2021'!$B14),0), SUM(_xlpm.x))} -> 208.8 | F14: {=_xlfn.LET(_xlpm.x,_xlfn._xlws.FILTER('Main Sheet'!$G$2:$G$564,(MONTH('Main Sheet'!$B$2:$B$564) = (COLUMN('Income & Expenses 2021'!F7) -3)) * ('Main Sheet'!$E$2:$E$564='Income & Expenses 2021'!$B14),0), SUM(_xlpm.x))} -> 237 | G14: {=_xlfn.LET(_xlpm.x,_xlfn._xlws.FILTER('Main Sheet'!$G$2:$G$564,(MONTH('Main Sheet'!$B$2:$B$564) = (COLUMN('Income & Expenses 2021'!G7) -3)) * ('Main Sheet'!$E$2:$E$564='Income & Expenses 2021'!$B14),0), SUM(_xlpm.x))} -> 240.1 | H14: {=_xlfn.LET(_xlpm.x,_xlfn._xlws.FILTER('Main Sheet'!$G$2:$G$564,(MONTH('Main Sheet'!$B$2:$B$564) = (COLUMN('Income & Expenses 2021'!H7) -3)) * ('Main Sheet'!$E$2:$E$564='Income & Expenses 2021'!$B14),0), SUM(_xlpm.x))} -> 243.2 | I14: {=_xlfn.LET(_xlpm.x,_xlfn._xlws.FILTER('Main Sheet'!$G$2:$G$564,(MONTH('Main Sheet'!$B$2:$B$564) = (COLUMN('Income & Expenses 2021'!I7) -3)) * ('Main Sheet'!$E$2:$E$564='Income & Expenses 2021'!$B14),0), SUM(_xlpm.x))} -> 241.1 | J14: {=_xlfn.LET(_xlpm.x,_xlfn._xlws.FILTER('Main Sheet'!$G$2:$G$564,(MONTH('Main Sheet'!$B$2:$B$564) = (COLUMN('Income & Expenses 2021'!J7) -3)) * ('Main Sheet'!$E$2:$E$564='Income & Expenses 2021'!$B14),0), SUM(_xlpm.x))} -> 259.3 | K14: {=_xlfn.LET(_xlpm.x,_xlfn._xlws.FILTER('Main Sheet'!$G$2:$G$564,(MONTH('Main Sheet'!$B$2:$B$564) = (COLUMN('Income & Expenses 2021'!K7) -3)) * ('Main Sheet'!$E$2:$E$564='Income & Expenses 2021'!$B14),0), SUM(_xlpm.x))} -> 252.5 | ... O14: {=_xlfn.LET(_xlpm.x,_xlfn._xlws.FILTER('Main Sheet'!$G$2:$G$564,(MONTH('Main Sheet'!$B$2:$B$564) = (COLUMN('Income & Expenses 2021'!O7) -3)) * ('Main Sheet'!$E$2:$E$564='Income & Expenses 2021'!$B14),0), SUM(_xlpm.x))} -> 157 | Q14: =IF(ISNUMBER(D14)=TRUE,SUM($D14:$O14),"") -> 2842.9
B15: Discretionary | C15: {=_xlfn.LET(_xlpm.x,_xlfn.UNIQUE(_xlfn._xlws.FILTER(tbl_main[Sub-category],tbl_main[Category]='Income & Expenses 2021'!B15)), _xlfn.ARRAYTOTEXT(_xlfn._xlws.SORT(_xlpm.x)))} -> Clothes, Entertainment, Furnishings, Gifts, Gym | D15: {=_xlfn.LET(_xlpm.x,_xlfn._xlws.FILTER('Main Sheet'!$G$2:$G$564,(MONTH('Main Sheet'!$B$2:$B$564) = (COLUMN('Income & Expenses 2021'!D8) -3)) * ('Main Sheet'!$E$2:$E$564='Income & Expenses 2021'!$B15),0), SUM(_xlpm.x))} -> 690 | E15: {=_xlfn.LET(_xlpm.x,_xlfn._xlws.FILTER('Main Sheet'!$G$2:$G$564,(MONTH('Main Sheet'!$B$2:$B$564) = (COLUMN('Income & Expenses 2021'!E8) -3)) * ('Main Sheet'!$E$2:$E$564='Income & Expenses 2021'!$B15),0), SUM(_xlpm.x))} -> 659.8 | F15: {=_xlfn.LET(_xlpm.x,_xlfn._xlws.FILTER('Main Sheet'!$G$2:$G$564,(MONTH('Main Sheet'!$B$2:$B$564) = (COLUMN('Income & Expenses 2021'!F8) -3)) * ('Main Sheet'!$E$2:$E$564='Income & Expenses 2021'!$B15),0), SUM(_xlpm.x))} -> 704.8 | G15: {=_xlfn.LET(_xlpm.x,_xlfn._xlws.FILTER('Main Sheet'!$G$2:$G$564,(MONTH('Main Sheet'!$B$2:$B$564) = (COLUMN('Income & Expenses 2021'!G8) -3)) * ('Main Sheet'!$E$2:$E$564='Income & Expenses 2021'!$B15),0), SUM(_xlpm.x))} -> 832.6 | H15: {=_xlfn.LET(_xlpm.x,_xlfn._xlws.FILTER('Main Sheet'!$G$2:$G$564,(MONTH('Main Sheet'!$B$2:$B$564) = (COLUMN('Income & Expenses 2021'!H8) -3)) * ('Main Sheet'!$E$2:$E$564='Income & Expenses 2021'!$B15),0), SUM(_xlpm.x))} -> 772.7 | I15: {=_xlfn.LET(_xlpm.x,_xlfn._xlws.FILTER('Main Sheet'!$G$2:$G$564,(MONTH('Main Sheet'!$B$2:$B$564) = (COLUMN('Income & Expenses 2021'!I8) -3)) * ('Main Sheet'!$E$2:$E$564='Income & Expenses 2021'!$B15),0), SUM(_xlpm.x))} -> 723.2 | J15: {=_xlfn.LET(_xlpm.x,_xlfn._xlws.FILTER('Main Sheet'!$G$2:$G$564,(MONTH('Main Sheet'!$B$2:$B$564) = (COLUMN('Income & Expenses 2021'!J8) -3)) * ('Main Sheet'!$E$2:$E$564='Income & Expenses 2021'!$B15),0), SUM(_xlpm.x))} -> 729.1 | K15: {=_xlfn.LET(_xlpm.x,_xlfn._xlws.FILTER('Main Sheet'!$G$2:$G$564,(MONTH('Main Sheet'!$B$2:$B$564) = (COLUMN('Income & Expenses 2021'!K8) -3)) * ('Main Sheet'!$E$2:$E$564='Income & Expenses 2021'!$B15),0), SUM(_xlpm.x))} -> 735.2 | ... O15: {=_xlfn.LET(_xlpm.x,_xlfn._xlws.FILTER('Main Sheet'!$G$2:$G$564,(MONTH('Main Sheet'!$B$2:$B$564) = (COLUMN('Income & Expenses 2021'!O8) -3)) * ('Main Sheet'!$E$2:$E$564='Income & Expenses 2021'!$B15),0), SUM(_xlpm.x))} -> 175 | Q15: =IF(ISNUMBER(D15)=TRUE,SUM($D15:$O15),"") -> 7916.6
B16: Living Expenses | C16: {=_xlfn.LET(_xlpm.x,_xlfn.UNIQUE(_xlfn._xlws.FILTER(tbl_main[Sub-category],tbl_main[Category]='Income & Expenses 2021'!B16)), _xlfn.ARRAYTOTEXT(_xlfn._xlws.SORT(_xlpm.x)))} -> Gas/Electrics, Groceries, Phone, Rent | D16: {=_xlfn.LET(_xlpm.x,_xlfn._xlws.FILTER('Main Sheet'!$G$2:$G$564,(MONTH('Main Sheet'!$B$2:$B$564) = (COLUMN('Income & Expenses 2021'!D9) -3)) * ('Main Sheet'!$E$2:$E$564='Income & Expenses 2021'!$B16),0), SUM(_xlpm.x))} -> 1612 | E16: {=_xlfn.LET(_xlpm.x,_xlfn._xlws.FILTER('Main Sheet'!$G$2:$G$564,(MONTH('Main Sheet'!$B$2:$B$564) = (COLUMN('Income & Expenses 2021'!E9) -3)) * ('Main Sheet'!$E$2:$E$564='Income & Expenses 2021'!$B16),0), SUM(_xlpm.x))} -> 1665.9 | F16: {=_xlfn.LET(_xlpm.x,_xlfn._xlws.FILTER('Main Sheet'!$G$2:$G$564,(MONTH('Main Sheet'!$B$2:$B$564) = (COLUMN('Income & Expenses 2021'!F9) -3)) * ('Main Sheet'!$E$2:$E$564='Income & Expenses 2021'!$B16),0), SUM(_xlpm.x))} -> 1659 | G16: {=_xlfn.LET(_xlpm.x,_xlfn._xlws.FILTER('Main Sheet'!$G$2:$G$564,(MONTH('Main Sheet'!$B$2:$B$564) = (COLUMN('Income & Expenses 2021'!G9) -3)) * ('Main Sheet'!$E$2:$E$564='Income & Expenses 2021'!$B16),0), SUM(_xlpm.x))} -> 1587.3 | H16: {=_xlfn.LET(_xlpm.x,_xlfn._xlws.FILTER('Main Sheet'!$G$2:$G$564,(MONTH('Main Sheet'!$B$2:$B$564) = (COLUMN('Income & Expenses 2021'!H9) -3)) * ('Main Sheet'!$E$2:$E$564='Income & Expenses 2021'!$B16),0), SUM(_xlpm.x))} -> 1643 | I16: {=_xlfn.LET(_xlpm.x,_xlfn._xlws.FILTER('Main Sheet'!$G$2:$G$564,(MONTH('Main Sheet'!$B$2:$B$564) = (COLUMN('Income & Expenses 2021'!I9) -3)) * ('Main Sheet'!$E$2:$E$564='Income & Expenses 2021'!$B16),0), SUM(_xlpm.x))} -> 1655.1 | J16: {=_xlfn.LET(_xlpm.x,_xlfn._xlws.FILTER('Main Sheet'!$G$2:$G$564,(MONTH('Main Sheet'!$B$2:$B$564) = (COLUMN('Income & Expenses 2021'!J9) -3)) * ('Main Sheet'!$E$2:$E$564='Income & Expenses 2021'!$B16),0), SUM(_xlpm.x))} -> 1686.2 | K16: {=_xlfn.LET(_xlpm.x,_xlfn._xlws.FILTER('Main Sheet'!$G$2:$G$564,(MONTH('Main Sheet'!$B$2:$B$564) = (COLUMN('Income & Expenses 2021'!K9) -3)) * ('Main Sheet'!$E$2:$E$564='Income & Expenses 2021'!$B16),0), SUM(_xlpm.x))} -> 1570.1 | ... O16: {=_xlfn.LET(_xlpm.x,_xlfn._xlws.FILTER('Main Sheet'!$G$2:$G$564,(MONTH('Main Sheet'!$B$2:$B$564) = (COLUMN('Income & Expenses 2021'!O9) -3)) * ('Main Sheet'!$E$2:$E$564='Income & Expenses 2021'!$B16),0), SUM(_xlpm.x))} -> 1309 | Q16: =IF(ISNUMBER(D16)=TRUE,SUM($D16:$O16),"") -> 19441.8
B17: Medical | C17: {=_xlfn.LET(_xlpm.x,_xlfn.UNIQUE(_xlfn._xlws.FILTER(tbl_main[Sub-category],tbl_main[Category]='Income & Expenses 2021'!B17)), _xlfn.ARRAYTOTEXT(_xlfn._xlws.SORT(_xlpm.x)))} -> Doctor | D17: {=_xlfn.LET(_xlpm.x,_xlfn._xlws.FILTER('Main Sheet'!$G$2:$G$564,(MONTH('Main Sheet'!$B$2:$B$564) = (COLUMN('Income & Expenses 2021'!D10) -3)) * ('Main Sheet'!$E$2:$E$564='Income & Expenses 2021'!$B17),0), SUM(_xlpm.x))} -> 1504 | E17: {=_xlfn.LET(_xlpm.x,_xlfn._xlws.FILTER('Main Sheet'!$G$2:$G$564,(MONTH('Main Sheet'!$B$2:$B$564) = (COLUMN('Income & Expenses 2021'!E10) -3)) * ('Main Sheet'!$E$2:$E$564='Income & Expenses 2021'!$B17),0), SUM(_xlpm.x))} -> 0 | F17: {=_xlfn.LET(_xlpm.x,_xlfn._xlws.FILTER('Main Sheet'!$G$2:$G$564,(MONTH('Main Sheet'!$B$2:$B$564) = (COLUMN('Income & Expenses 2021'!F10) -3)) * ('Main Sheet'!$E$2:$E$564='Income & Expenses 2021'!$B17),0), SUM(_xlpm.x))} -> 75 | G17: {=_xlfn.LET(_xlpm.x,_xlfn._xlws.FILTER('Main Sheet'!$G$2:$G$564,(MONTH('Main Sheet'!$B$2:$B$564) = (COLUMN('Income & Expenses 2021'!G10) -3)) * ('Main Sheet'!$E$2:$E$564='Income & Expenses 2021'!$B17),0), SUM(_xlpm.x))} -> 0 | H17: {=_xlfn.LET(_xlpm.x,_xlfn._xlws.FILTER('Main Sheet'!$G$2:$G$564,(MONTH('Main Sheet'!$B$2:$B$564) = (COLUMN('Income & Expenses 2021'!H10) -3)) * ('Main Sheet'!$E$2:$E$564='Income & Expenses 2021'!$B17),0), SUM(_xlpm.x))} -> 75 | I17: {=_xlfn.LET(_xlpm.x,_xlfn._xlws.FILTER('Main Sheet'!$G$2:$G$564,(MONTH('Main Sheet'!$B$2:$B$564) = (COLUMN('Income & Expenses 2021'!I10) -3)) * ('Main Sheet'!$E$2:$E$564='Income & Expenses 2021'!$B17),0), SUM(_xlpm.x))} -> 0 | J17: {=_xlfn.LET(_xlpm.x,_xlfn._xlws.FILTER('Main Sheet'!$G$2:$G$564,(MONTH('Main Sheet'!$B$2:$B$564) = (COLUMN('Income & Expenses 2021'!J10) -3)) * ('Main Sheet'!$E$2:$E$564='Income & Expenses 2021'!$B17),0), SUM(_xlpm.x))} -> 0 | K17: {=_xlfn.LET(_xlpm.x,_xlfn._xlws.FILTER('Main Sheet'!$G$2:$G$564,(MONTH('Main Sheet'!$B$2:$B$564) = (COLUMN('Income & Expenses 2021'!K10) -3)) * ('Main Sheet'!$E$2:$E$564='Income & Expenses 2021'!$B17),0), SUM(_xlpm.x))} -> 0 | ... O17: {=_xlfn.LET(_xlpm.x,_xlfn._xlws.FILTER('Main Sheet'!$G$2:$G$564,(MONTH('Main Sheet'!$B$2:$B$564) = (COLUMN('Income & Expenses 2021'!O10) -3)) * ('Main Sheet'!$E$2:$E$564='Income & Expenses 2021'!$B17),0), SUM(_xlpm.x))} -> 0 | Q17: =IF(ISNUMBER(D17)=TRUE,SUM($D17:$O17),"") -> 1729
B18: Transport | C18: {=_xlfn.LET(_xlpm.x,_xlfn.UNIQUE(_xlfn._xlws.FILTER(tbl_main[Sub-category],tbl_main[Category]='Income & Expenses 2021'!B18)), _xlfn.ARRAYTOTEXT(_xlfn._xlws.SORT(_xlpm.x)))} -> Entertainment, MV Fuel, Taxi | D18: {=_xlfn.LET(_xlpm.x,_xlfn._xlws.FILTER('Main Sheet'!$G$2:$G$564,(MONTH('Main Sheet'!$B$2:$B$564) = (COLUMN('Income & Expenses 2021'!D11) -3)) * ('Main Sheet'!$E$2:$E$564='Income & Expenses 2021'!$B18),0), SUM(_xlpm.x))} -> 341 | E18: {=_xlfn.LET(_xlpm.x,_xlfn._xlws.FILTER('Main Sheet'!$G$2:$G$564,(MONTH('Main Sheet'!$B$2:$B$564) = (COLUMN('Income & Expenses 2021'!E11) -3)) * ('Main Sheet'!$E$2:$E$564='Income & Expenses 2021'!$B18),0), SUM(_xlpm.x))} -> 345.1 | F18: {=_xlfn.LET(_xlpm.x,_xlfn._xlws.FILTER('Main Sheet'!$G$2:$G$564,(MONTH('Main Sheet'!$B$2:$B$564) = (COLUMN('Income & Expenses 2021'!F11) -3)) * ('Main Sheet'!$E$2:$E$564='Income & Expenses 2021'!$B18),0), SUM(_xlpm.x))} -> 348.9 | G18: {=_xlfn.LET(_xlpm.x,_xlfn._xlws.FILTER('Main Sheet'!$G$2:$G$564,(MONTH('Main Sheet'!$B$2:$B$564) = (COLUMN('Income & Expenses 2021'!G11) -3)) * ('Main Sheet'!$E$2:$E$564='Income & Expenses 2021'!$B18),0), SUM(_xlpm.x))} -> 353 | H18: {=_xlfn.LET(_xlpm.x,_xlfn._xlws.FILTER('Main Sheet'!$G$2:$G$564,(MONTH('Main Sheet'!$B$2:$B$564) = (COLUMN('Income & Expenses 2021'!H11) -3)) * ('Main Sheet'!$E$2:$E$564='Income & Expenses 2021'!$B18),0), SUM(_xlpm.x))} -> 357.2 | I18: {=_xlfn.LET(_xlpm.x,_xlfn._xlws.FILTER('Main Sheet'!$G$2:$G$564,(MONTH('Main Sheet'!$B$2:$B$564) = (COLUMN('Income & Expenses 2021'!I11) -3)) * ('Main Sheet'!$E$2:$E$564='Income & Expenses 2021'!$B18),0), SUM(_xlpm.x))} -> 361.3 | J18: {=_xlfn.LET(_xlpm.x,_xlfn._xlws.FILTER('Main Sheet'!$G$2:$G$564,(MONTH('Main Sheet'!$B$2:$B$564) = (COLUMN('Income & Expenses 2021'!J11) -3)) * ('Main Sheet'!$E$2:$E$564='Income & Expenses 2021'!$B18),0), SUM(_xlpm.x))} -> 365.4 | K18: {=_xlfn.LET(_xlpm.x,_xlfn._xlws.FILTER('Main Sheet'!$G$2:$G$564,(MONTH('Main Sheet'!$B$2:$B$564) = (COLUMN('Income & Expenses 2021'!K11) -3)) * ('Main Sheet'!$E$2:$E$564='Income & Expenses 2021'!$B18),0), SUM(_xlpm.x))} -> 369.3 | ... O18: {=_xlfn.LET(_xlpm.x,_xlfn._xlws.FILTER('Main Sheet'!$G$2:$G$564,(MONTH('Main Sheet'!$B$2:$B$564) = (COLUMN('Income & Expenses 2021'!O11) -3)) * ('Main Sheet'!$E$2:$E$564='Income & Expenses 2021'!$B18),0), SUM(_xlpm.x))} -> 272 | Q18: =IF(ISNUMBER(D18)=TRUE,SUM($D18:$O18),"") -> 4244.7
B19: Total Expenses | D19: =SUM(D13:D18) -> 4423 | E19: =SUM(E13:E18) -> 2934.6 | F19: =SUM(F13:F18) -> 3079.7 | G19: =SUM(G13:G18) -> 3068 | H19: =SUM(H13:H18) -> 3146.1 | I19: =SUM(I13:I18) -> 3035.7 | J19: =SUM(J13:J18) -> 3095 | K19: =SUM(K13:K18) -> 2982.1 | ... O19: =SUM(O13:O18) -> 1913 | Q19: =IF(ISNUMBER(D19)=TRUE,SUM($D19:$O19),"") -> 36795
Q20: =IF(ISNUMBER(D20)=TRUE,SUM($D20:$O20),"")
B21: Savings | D21: =D9-D19 -> -423 | E21: =E9-E19 -> 1065.4 | F21: =F9-F19 -> 920.3 | G21: =G9-G19 -> 932 | H21: =H9-H19 -> 853.9 | I21: =I9-I19 -> 964.3 | J21: =J9-J19 -> 905 | K21: =K9-K19 -> 1017.9 | ... O21: =O9-O19 -> 2087 | Q21: =IF(ISNUMBER(D21)=TRUE,SUM($D21:$O21),"") -> 11205
B22: Cumulative Savings | D22: =D21 -> -423 | E22: =SUM(D22,E21) -> 642.4 | F22: =SUM(E22,F21) -> 1562.7 | G22: =SUM(F22,G21) -> 2494.7 | H22: =SUM(G22,H21) -> 3348.6 | I22: =SUM(H22,I21) -> 4312.9 | J22: =SUM(I22,J21) -> 5217.9 | K22: =SUM(J22,K21) -> 6235.8 | L22: =SUM(K22,L21) -> 7118.7 | ... O22: =SUM(N22,O21) -> 11205 | Q22: =O22 -> 11205

Sheet Pivot Table
A1: Total | D1: Total Income & Expenses by Month | I1: Total by Category Type | L1: Total by Category | P1: Total by Sub-Category | S1: Total by Sub-Category
A4: Sum of Credit | D4: Row Labels | E4: Sum of Credit | F4: Sum of Debit | G4: Sum of Saving | I4: Row Labels | J4: Sum of Amount | L4: Row Labels | M4: Sum of Debit | P4: Row Labels | Q4: Sum of Debit | S4: Row Labels | T4: Sum of Debit
A5: 48000 | D5: Jan | E5: 4000 | F5: 4423 | G5: -423 | I5: Income | J5: 48000 | L5: Charity | M5: 0.016850116 | P5: Clothes | Q5: 4690.6 | S5: BW Club | T5: 300
D6: Feb | E6: 4000 | F6: 2934.6 | G6: 642.4 | I6: Expense | J6: -36795 | L6: Dining Out | M6: 0.077263215 | P6: Coffee | Q6: 1315 | S6: Elec. Co. | T6: 643.7
A7: Sum of Debit | D7: Mar | E7: 4000 | F7: 3079.7 | G7: 1562.7 | L7: Discretionary | M7: 0.21515423 | P7: Doctor | Q7: 1729 | S7: Estate Mgt. | T7: 10854
A8: 36795 | D8: Apr | E8: 4000 | F8: 3068 | G8: 2494.7 | L8: Living Expenses | M8: 0.52838157 | P8: Donation | Q8: 620 | S8: Event Cinemas | T8: 515.5
D9: May | E9: 4000 | F9: 3146.1 | G9: 3348.6 | L9: Medical | M9: 0.04699008 | P9: Entertainment | Q9: 3754.6 | S9: Fashionistas | T9: 2907.5
A10: Sum of Amount | D10: Jun | E10: 4000 | F10: 3035.7 | G10: 4312.9 | L10: Salary | M10: 0 | P10: Furnishings | Q10: 416.4 | S10: Finance Co. | T10: 1800
A11: 11205 | D11: Jul | E11: 4000 | F11: 3095 | G11: 5217.9 | L11: Transport | M11: 0.11536078 | P11: Gas/Electrics | Q11: 643.7 | S11: Fodary | T11: 15
D12: Aug | E12: 4000 | F12: 2982.1 | G12: 6235.8 | P12: Gifts | Q12: 495 | S12: Foodary | T12: 150
A13: % Money Saving | D13: Sep | E13: 4000 | F13: 3117.1 | G13: 7118.7 | P13: Groceries | Q13: 7464.1 | S13: Fuel. Co | T13: 1746.5
A14: =A11/A5 -> 0.2334375 | D14: Oct | E14: 4000 | F14: 3128.7 | G14: 7990 | P14: Gym | Q14: 360 | S14: Global Fashion | T14: 312
D15: Nov | E15: 4000 | F15: 2872 | G15: 9118 | P15: MV Fuel | Q15: 1746.5 | S15: Golden Arches | T15: 178.9
D16: Dec | E16: 4000 | F16: 1913 | G16: 11205 | P16: Phone | Q16: 480 | S16: Green's | T16: 7464.1
P17: Rent | Q17: 10854 | S17: Ground | T17: 1315
P18: Restaurant | Q18: 1527.9 | S18: Home Decorator | T18: 416.4
P19: Taxi | Q19: 698.2 | S19: Joe's Grill | T19: 709
D20: Month | E20: Salary | F20: Expenses | S20: Muscle Beach | T20: 360
D21: {=D5:F16} -> Jan | E21: 4000 | F21: 4423 | S21: Phone Co. | T21: 480
D22: Feb | E22: 4000 | F22: 2934.6 | S22: Pizza Pomodoro | T22: 475
D23: Mar | E23: 4000 | F23: 3079.7 | P23: {=P5:Q19} -> Clothes | Q23: 4690.6 | S23: Sam's Gifts | T23: 495
D24: Apr | E24: 4000 | F24: 3068 | P24: Coffee | Q24: 1315 | S24: Smile Dental | T24: 1504
D25: May | E25: 4000 | F25: 3146.1 | P25: Doctor | Q25: 1729 | S25: Sports Co. | T25: 177.2
D26: Jun | E26: 4000 | F26: 3035.7 | P26: Donation | Q26: 620 | S26: Streaming Co. | T26: 417
D27: Jul | E27: 4000 | F27: 3095 | P27: Entertainment | Q27: 3754.6 | S27: Taxi Co. | T27: 698.2
D28: Aug | E28: 4000 | F28: 2982.1 | P28: Furnishings | Q28: 416.4 | S28: Ted's Trainers | T28: 1293.9
D29: Sep | E29: 4000 | F29: 3117.1 | P29: Gas/Electrics | Q29: 643.7 | S29: Ticketek | T29: 722.1
D30: Oct | E30: 4000 | F30: 3128.7 | P30: Gifts | Q30: 495 | S30: Village Medical | T30: 225
D31: Nov | E31: 4000 | F31: 2872 | P31: Groceries | Q31: 7464.1 | S31: Worldvision | T31: 620
D32: Dec | E32: 4000 | F32: 1913 | P32: Gym | Q32: 360
P33: MV Fuel | Q33: 1746.5
P34: Phone | Q34: 480
P35: Rent | Q35: 10854
P36: Restaurant | Q36: 1527.9
P37: Taxi | Q37: 698.2

Sheet Dashboard
